Workbook
Name AirDensity: Assumptions!$B$6
Name Cd: Assumptions!$B$9
Name ClDown: Assumptions!$B$8
Name DRSDragMultiplier: Assumptions!$B$16
Name DRSRearMultiplier: Assumptions!$B$17
Name Friction: Assumptions!$B$12
Name FrontFraction: Assumptions!$B$10
Name Gravity: Assumptions!$B$11
Name Mass: Assumptions!$B$13
Name Radius: Assumptions!$B$14
Name ReferenceArea: Assumptions!$B$7
Name Tolerance: Assumptions!$B$15

Sheet Lap Summary
A2: Lap Summary
A3: SYNTHETIC RESEARCH MODEL | SI units | model 1.0.0
A4: Nominal dry qualifying comparison. Candidate minus baseline: negative is faster.
A5: Circuit | B5: Baseline (s) | C5: Candidate (s) | D5: Delta (s) | E5: Top speed (m/s) | F5: DRS gain (s) | G5: Setup ID | H5: Violations
A6: Velocity Park | B6: 49.597523 | C6: 49.232189 | D6: =C6-B6 -> -0.36533357 | E6: 87.027223 | F6: 0.38933923 | G6: 13 | H6: 0
A7: Apex Ring | B7: 38.869327 | C7: 38.348409 | D7: =C7-B7 -> -0.52091806 | E7: 89.015598 | F7: 0.2948148 | G7: 14 | H7: 0
A8: Downforce Circuit | B8: 27.654403 | C8: 26.517366 | D8: =C8-B8 -> -1.1370366 | E8: 92.046966 | F8: 0.25649578 | G8: 15 | H8: 0

Sheet Setup Comparison
A2: Setup Comparison
A3: SYNTHETIC RESEARCH MODEL | SI units | model 1.0.0
A5: setup_id | B5: setup_name | C5: front_wing_deg | D5: rear_wing_deg | E5: front_height_m | F5: rear_height_m | G5: package
A6: 1 | B6: Baseline | C6: 17.5 | D6: 20 | E6: 0.04 | F6: 0.06 | G6: standard
A7: 2 | B7: Candidate 01 | C7: 20.787473 | D7: 19.022055 | E7: 0.04860635 | F7: 0.069605249 | G7: standard
A8: 3 | B8: Candidate 02 | C8: 12.630128 | D8: 27.609958 | E8: 0.046267353 | F8: 0.072798315 | G8: standard
A9: 4 | B9: Candidate 03 | C9: 13.037364 | D9: 19.206175 | E9: 0.036899153 | F9: 0.07786354 | G9: standard
A10: 5 | B10: Candidate 04 | C10: 19.226381 | D10: 25.164186 | E10: 0.038641941 | F10: 0.052680594 | G10: standard
A11: 6 | B11: Candidate 05 | C11: 18.155017 | D11: 13.021076 | E11: 0.047863148 | F11: 0.067239918 | G11: standard
A12: 7 | B12: Candidate 06 | C12: 20.597053 | D12: 17.672415 | E12: 0.051296753 | F12: 0.07665236 | G12: standard
A13: 8 | B13: Candidate 07 | C13: 20.840602 | D13: 15.114219 | E13: 0.039201304 | F13: 0.046076936 | G13: standard
A14: 9 | B14: Candidate 08 | C14: 13.351474 | D14: 22.928783 | E14: 0.045874292 | F14: 0.07933035 | G14: standard
A15: 10 | B15: Candidate 09 | C15: 15.409904 | D15: 17.927355 | E15: 0.039269339 | F15: 0.051320969 | G15: standard
A16: 11 | B16: Candidate 10 | C16: 13.059058 | D16: 19.611279 | E16: 0.033445824 | F16: 0.068613304 | G16: standard
A17: 12 | B17: Candidate 11 | C17: 16.745823 | D17: 25.322851 | E17: 0.044806362 | F17: 0.055745199 | G17: standard
... A20: 15 | B20: Downforce Circuit qualifying | C20: 12.477897 | D20: 10.038388 | E20: 0.038372825 | F20: 0.055092893 | G20: standard

Sheet Assumptions
A2: Assumptions
A3: SYNTHETIC RESEARCH MODEL | SI units | model 1.0.0
A5: input | B5: value | C5: unit
A6: AirDensity | B6: 1.225 | C6: kg/m3
A7: ReferenceArea | B7: 1.5 | C7: m2
A8: ClDown | B8: 3 | C8: dimensionless
A9: Cd | B9: 0.9 | C9: dimensionless
A10: FrontFraction | B10: 0.44 | C10: fraction
A11: Gravity | B11: 9.80665 | C11: m/s2
A12: Friction | B12: 1.6 | C12: reference mu
A13: Mass | B13: 810 | C13: kg
A14: Radius | B14: 100 | C14: m
A15: Tolerance | B15: 1e-06 | C15: relative
A16: DRSDragMultiplier | B16: 0.82 | C16: fraction
A17: DRSRearMultiplier | B17: 0.75 | C17: fraction

Sheet Aero Calculations
A2: Aero Calculations
A3: SYNTHETIC RESEARCH MODEL | SI units | model 1.0.0
A4: Independent scalar equations with constant coefficients. Live editable assumptions.
A5: speed_mps | B5: q_pa | C5: downforce_n | D5: drag_n | E5: front_n | F5: rear_n | G5: front_fraction | H5: rear_fraction | I5: aero_efficiency | J5: drag_power_w | K5: DRS_drag_n | L5: drag_reduction_n
A6: 0 | B6: =0.5*AirDensity*A6^2 -> 0 | C6: =B6*ReferenceArea*ClDown -> 0 | D6: =B6*ReferenceArea*Cd -> 0 | E6: =C6*FrontFraction -> 0 | F6: =C6-E6 -> 0 | G6: =IF(C6=0,"n.a.",E6/C6) -> n.a. | H6: =IF(C6=0,"n.a.",F6/C6) -> n.a. | I6: =IF(D6=0,"n.a.",C6/D6) -> n.a. | J6: =D6*A6 -> 0 | K6: =D6*DRSDragMultiplier -> 0 | L6: =D6-K6 -> 0
A7: 5 | B7: =0.5*AirDensity*A7^2 -> 15.3125 | C7: =B7*ReferenceArea*ClDown -> 68.90625 | D7: =B7*ReferenceArea*Cd -> 20.671875 | E7: =C7*FrontFraction -> 30.31875 | F7: =C7-E7 -> 38.5875 | G7: =IF(C7=0,"n.a.",E7/C7) -> 0.44 | H7: =IF(C7=0,"n.a.",F7/C7) -> 0.56 | I7: =IF(D7=0,"n.a.",C7/D7) -> 3.3333333 | J7: =D7*A7 -> 103.35938 | K7: =D7*DRSDragMultiplier -> 16.950938 | L7: =D7-K7 -> 3.7209375
A8: 10 | B8: =0.5*AirDensity*A8^2 -> 61.25 | C8: =B8*ReferenceArea*ClDown -> 275.625 | D8: =B8*ReferenceArea*Cd -> 82.6875 | E8: =C8*FrontFraction -> 121.275 | F8: =C8-E8 -> 154.35 | G8: =IF(C8=0,"n.a.",E8/C8) -> 0.44 | H8: =IF(C8=0,"n.a.",F8/C8) -> 0.56 | I8: =IF(D8=0,"n.a.",C8/D8) -> 3.3333333 | J8: =D8*A8 -> 826.875 | K8: =D8*DRSDragMultiplier -> 67.80375 | L8: =D8-K8 -> 14.88375
A9: 15 | B9: =0.5*AirDensity*A9^2 -> 137.8125 | C9: =B9*ReferenceArea*ClDown -> 620.15625 | D9: =B9*ReferenceArea*Cd -> 186.04688 | E9: =C9*FrontFraction -> 272.86875 | F9: =C9-E9 -> 347.2875 | G9: =IF(C9=0,"n.a.",E9/C9) -> 0.44 | H9: =IF(C9=0,"n.a.",F9/C9) -> 0.56 | I9: =IF(D9=0,"n.a.",C9/D9) -> 3.3333333 | J9: =D9*A9 -> 2790.7031 | K9: =D9*DRSDragMultiplier -> 152.55844 | L9: =D9-K9 -> 33.488438
A10: 20 | B10: =0.5*AirDensity*A10^2 -> 245 | C10: =B10*ReferenceArea*ClDown -> 1102.5 | D10: =B10*ReferenceArea*Cd -> 330.75 | E10: =C10*FrontFraction -> 485.1 | F10: =C10-E10 -> 617.4 | G10: =IF(C10=0,"n.a.",E10/C10) -> 0.44 | H10: =IF(C10=0,"n.a.",F10/C10) -> 0.56 | I10: =IF(D10=0,"n.a.",C10/D10) -> 3.3333333 | J10: =D10*A10 -> 6615 | K10: =D10*DRSDragMultiplier -> 271.215 | L10: =D10-K10 -> 59.535
A11: 25 | B11: =0.5*AirDensity*A11^2 -> 382.8125 | C11: =B11*ReferenceArea*ClDown -> 1722.6562 | D11: =B11*ReferenceArea*Cd -> 516.79688 | E11: =C11*FrontFraction -> 757.96875 | F11: =C11-E11 -> 964.6875 | G11: =IF(C11=0,"n.a.",E11/C11) -> 0.44 | H11: =IF(C11=0,"n.a.",F11/C11) -> 0.56 | I11: =IF(D11=0,"n.a.",C11/D11) -> 3.3333333 | J11: =D11*A11 -> 12919.922 | K11: =D11*DRSDragMultiplier -> 423.77344 | L11: =D11-K11 -> 93.023438
A12: 30 | B12: =0.5*AirDensity*A12^2 -> 551.25 | C12: =B12*ReferenceArea*ClDown -> 2480.625 | D12: =B12*ReferenceArea*Cd -> 744.1875 | E12: =C12*FrontFraction -> 1091.475 | F12: =C12-E12 -> 1389.15 | G12: =IF(C12=0,"n.a.",E12/C12) -> 0.44 | H12: =IF(C12=0,"n.a.",F12/C12) -> 0.56 | I12: =IF(D12=0,"n.a.",C12/D12) -> 3.3333333 | J12: =D12*A12 -> 22325.625 | K12: =D12*DRSDragMultiplier -> 610.23375 | L12: =D12-K12 -> 133.95375
A13: 35 | B13: =0.5*AirDensity*A13^2 -> 750.3125 | C13: =B13*ReferenceArea*ClDown -> 3376.4062 | D13: =B13*ReferenceArea*Cd -> 1012.9219 | E13: =C13*FrontFraction -> 1485.6188 | F13: =C13-E13 -> 1890.7875 | G13: =IF(C13=0,"n.a.",E13/C13) -> 0.44 | H13: =IF(C13=0,"n.a.",F13/C13) -> 0.56 | I13: =IF(D13=0,"n.a.",C13/D13) -> 3.3333333 | J13: =D13*A13 -> 35452.266 | K13: =D13*DRSDragMultiplier -> 830.59594 | L13: =D13-K13 -> 182.32594
A14: 40 | B14: =0.5*AirDensity*A14^2 -> 980 | C14: =B14*ReferenceArea*ClDown -> 4410 | D14: =B14*ReferenceArea*Cd -> 1323 | E14: =C14*FrontFraction -> 1940.4 | F14: =C14-E14 -> 2469.6 | G14: =IF(C14=0,"n.a.",E14/C14) -> 0.44 | H14: =IF(C14=0,"n.a.",F14/C14) -> 0.56 | I14: =IF(D14=0,"n.a.",C14/D14) -> 3.3333333 | J14: =D14*A14 -> 52920 | K14: =D14*DRSDragMultiplier -> 1084.86 | L14: =D14-K14 -> 238.14
A15: 45 | B15: =0.5*AirDensity*A15^2 -> 1240.3125 | C15: =B15*ReferenceArea*ClDown -> 5581.4062 | D15: =B15*ReferenceArea*Cd -> 1674.4219 | E15: =C15*FrontFraction -> 2455.8187 | F15: =C15-E15 -> 3125.5875 | G15: =IF(C15=0,"n.a.",E15/C15) -> 0.44 | H15: =IF(C15=0,"n.a.",F15/C15) -> 0.56 | I15: =IF(D15=0,"n.a.",C15/D15) -> 3.3333333 | J15: =D15*A15 -> 75348.984 | K15: =D15*DRSDragMultiplier -> 1373.0259 | L15: =D15-K15 -> 301.39594
A16: 50 | B16: =0.5*AirDensity*A16^2 -> 1531.25 | C16: =B16*ReferenceArea*ClDown -> 6890.625 | D16: =B16*ReferenceArea*Cd -> 2067.1875 | E16: =C16*FrontFraction -> 3031.875 | F16: =C16-E16 -> 3858.75 | G16: =IF(C16=0,"n.a.",E16/C16) -> 0.44 | H16: =IF(C16=0,"n.a.",F16/C16) -> 0.56 | I16: =IF(D16=0,"n.a.",C16/D16) -> 3.3333333 | J16: =D16*A16 -> 103359.38 | K16: =D16*DRSDragMultiplier -> 1695.0938 | L16: =D16-K16 -> 372.09375
A17: 55 | B17: =0.5*AirDensity*A17^2 -> 1852.8125 | C17: =B17*ReferenceArea*ClDown -> 8337.6563 | D17: =B17*ReferenceArea*Cd -> 2501.2969 | E17: =C17*FrontFraction -> 3668.5688 | F17: =C17-E17 -> 4669.0875 | G17: =IF(C17=0,"n.a.",E17/C17) -> 0.44 | H17: =IF(C17=0,"n.a.",F17/C17) -> 0.56 | I17: =IF(D17=0,"n.a.",C17/D17) -> 3.3333333 | J17: =D17*A17 -> 137571.33 | K17: =D17*DRSDragMultiplier -> 2051.0634 | L17: =D17-K17 -> 450.23344
... A26: 100 | B26: =0.5*AirDensity*A26^2 -> 6125 | C26: =B26*ReferenceArea*ClDown -> 27562.5 | D26: =B26*ReferenceArea*Cd -> 8268.75 | E26: =C26*FrontFraction -> 12127.5 | F26: =C26-E26 -> 15435 | G26: =IF(C26=0,"n.a.",E26/C26) -> 0.44 | H26: =IF(C26=0,"n.a.",F26/C26) -> 0.56 | I26: =IF(D26=0,"n.a.",C26/D26) -> 3.3333333 | J26: =D26*A26 -> 826875 | K26: =D26*DRSDragMultiplier -> 6780.375 | L26: =D26-K26 -> 1488.375

Sheet Lap-Time Model
A2: Lap-Time Model
A3: SYNTHETIC RESEARCH MODEL | SI units | model 1.0.0
A4: Limiting-case equations; the full integrated lap is imported in Lap Summary.
A5: quantity | B5: value | C5: unit
A6: Initial speed | B6: 80 | C6: m/s
A7: Target speed | B7: 30 | C7: m/s
A8: Constant deceleration | B8: 15 | C8: m/s2
A9: Braking distance | B9: =(B6^2-B7^2)/(2*B8) -> 183.33333 | C9: m
A10: Braking time | B10: =(B6-B7)/B8 -> 3.3333333 | C10: s
A11: Straight distance | B11: 500 | C11: m
A12: Constant straight speed | B12: 50 | C12: m/s
A13: Straight time | B13: =B11/B12 -> 10 | C13: s
A14: Mechanical corner speed | B14: =SQRT(Friction*Gravity*Radius) -> 39.611412 | C14: m/s

Sheet Sector Comparison
A2: Sector Comparison
A3: SYNTHETIC RESEARCH MODEL | SI units | model 1.0.0
A5: sector_id | B5: sector_time_s_baseline | C5: sector_time_s_candidate | D5: delta_s
A6: 21 | B6: 12.303661 | C6: 11.999311 | D6: =C6-B6 -> -0.30435064
A7: 22 | B7: 14.544435 | C7: 14.529981 | D7: =C7-B7 -> -0.014454104
A8: 23 | B8: 12.02123 | C8: 11.819117 | D8: =C8-B8 -> -0.20211332

Sheet DRS Analysis
A2: DRS Analysis
A3: SYNTHETIC RESEARCH MODEL | SI units | model 1.0.0
A4: Paired same-setup, same-weather laps; gain is off minus on.
A5: pair_id | B5: lap_time_s_off | C5: top_speed_mps_off | D5: lap_time_s_on | E5: top_speed_mps_on | F5: time_gain_s | G5: top_speed_gain_mps
A6: 1 | B6: 39.152518 | C6: 80.965526 | D6: 38.869327 | E6: 84.174868 | F6: =B6-D6 -> 0.28319097 | G6: 3.2093414
A7: 2 | B7: 39.430533 | C7: 80.157977 | D7: 39.131569 | E7: 83.656428 | F7: =B7-D7 -> 0.29896418 | G7: 3.4984515
A8: 3 | B8: 40.511925 | C8: 76.913433 | D8: 40.088539 | E8: 80.511995 | F8: =B8-D8 -> 0.42338614 | G8: 3.5985613

Sheet Sensitivity Analysis
A2: Sensitivity Analysis
A3: SYNTHETIC RESEARCH MODEL | SI units | model 1.0.0
A4: Apex Ring; ±5% parameter-domain perturbation. Full simulator snapshots.
A5: parameter | B5: direction | C5: change | D5: delta_s | E5: status
A6: front_wing_deg | B6: -1 | C6: -0.75 | D6: 0.049061996 | E6: simulated
A7: front_wing_deg | B7: 1 | C7: 0.75 | D7: 0.037687351 | E7: simulated
A8: rear_wing_deg | B8: -1 | C8: -1 | D8: 0.068386389 | E8: simulated
A9: rear_wing_deg | B9: 1 | C9: 1 | D9: 0.045123005 | E9: simulated
A10: front_height_m | B10: -1 | C10: -0.0015 | D10: 0.04825391 | E10: simulated
A11: front_height_m | B11: 1 | C11: 0.0015 | D11: -0.02808786 | E11: simulated
A12: rear_height_m | B12: -1 | C12: -0.00225 | D12: 0.012236075 | E12: simulated
A13: rear_height_m | B13: 1 | C13: 0.00225 | D13: -0.0035691186 | E13: simulated

Sheet Optimization Results
A2: Optimization Results
A3: SYNTHETIC RESEARCH MODEL | SI units | model 1.0.0
A5: circuit | B5: seed | C5: method | D5: front_wing_deg | E5: rear_wing_deg | F5: front_height_m | G5: rear_height_m | H5: lap_time_s | I5: objective_value | J5: feasible | K5: pareto | L5: constraint_reasons
A6: Velocity Park | B6: 42 | C6: local | D6: 16.53228 | E6: 15.180592 | F6: 0.035168956 | G6: 0.060726211 | H6: 49.067068 | I6: 49.067068 | J6: TRUE | K6: TRUE
A7: Velocity Park | B7: 42 | C7: local | D7: 16.53228 | E7: 15.160532 | F7: 0.035168956 | G7: 0.060726211 | H7: 49.067522 | I7: 49.067522 | J7: TRUE | K7: TRUE
A8: Velocity Park | B8: 42 | C8: local | D8: 16.53228 | E8: 15.198032 | F8: 0.035168956 | G8: 0.060726211 | H8: 49.067638 | I8: 49.067638 | J8: TRUE | K8: FALSE
A9: Velocity Park | B9: 42 | C9: local | D9: 16.53228 | E9: 15.154716 | F9: 0.035168956 | G9: 0.060726211 | H9: 49.067689 | I9: 49.067689 | J9: TRUE | K9: TRUE
A10: Velocity Park | B10: 42 | C10: local | D10: 16.53228 | E10: 15.226251 | F10: 0.035168956 | G10: 0.060726211 | H10: 49.068576 | I10: 49.068576 | J10: TRUE | K10: FALSE
A11: Velocity Park | B11: 42 | C11: local | D11: 16.53228 | E11: 15.025858 | F11: 0.035168956 | G11: 0.060726211 | H11: 49.071435 | I11: 49.071435 | J11: TRUE | K11: TRUE
A12: Velocity Park | B12: 42 | C12: differential_evolution | D12: 17.929057 | E12: 15.675507 | F12: 0.035168956 | G12: 0.060726211 | H12: 49.079238 | I12: 49.079238 | J12: TRUE | K12: FALSE
A13: Velocity Park | B13: 42 | C13: local | D13: 16.53228 | E13: 15.583494 | F13: 0.035168956 | G13: 0.060726211 | H13: 49.080785 | I13: 49.080785 | J13: TRUE | K13: FALSE
A14: Velocity Park | B14: 42 | C14: local | D14: 16.53228 | E14: 14.72136 | F14: 0.035168956 | G14: 0.060726211 | H14: 49.081005 | I14: 49.081005 | J14: TRUE | K14: TRUE
A15: Velocity Park | B15: 42 | C15: local | D15: 16.53228 | E15: 15.675507 | F15: 0.035168956 | G15: 0.060726211 | H15: 49.084033 | I15: 49.084033 | J15: TRUE | K15: FALSE
A16: Velocity Park | B16: 42 | C16: local | D16: 16.528946 | E16: 15.675507 | F16: 0.035168956 | G16: 0.060726211 | H16: 49.08404 | I16: 49.08404 | J16: TRUE | K16: FALSE
A17: Velocity Park | B17: 42 | C17: local | D17: 16.535864 | E17: 15.675507 | F17: 0.035168956 | G17: 0.060726211 | H17: 49.084072 | I17: 49.084072 | J17: TRUE | K17: FALSE
... A95: Velocity Park | B95: 42 | C95: differential_evolution | D95: 24.426885 | E95: 29.089186 | F95: 0.054678883 | G95: 0.041683727 | H95: 51.080237 | I95: 51.080237 | J95: TRUE | K95: FALSE
A96: Velocity Park | B96: 42 | C96: random | D96: 10.340681 | E96: 11.800957 | F96: 0.046670781 | G96: 0.060784475 | H96: 49.486471 | I96: 49.486471 | J96: FALSE | K96: FALSE | L96: braking_limit
A97: Velocity Park | B97: 42 | C97: differential_evolution | D97: 19.97819 | E97: 10.093097 | F97: 0.034922771 | G97: 0.053729123 | H97: 49.572645 | I97: 49.572645 | J97: FALSE | K97: FALSE | L97: balance
A98: Velocity Park | B98: 42 | C98: differential_evolution | D98: 20.37348 | E98: 10.783071 | F98: 0.034372805 | G98: 0.067518117 | H98: 49.61493 | I98: 49.61493 | J98: FALSE | K98: FALSE | L98: balance
A99: Velocity Park | B99: 42 | C99: differential_evolution | D99: 23.207962 | E99: 11.188393 | F99: 0.050496062 | G99: 0.052069082 | H99: 50.305805 | I99: 50.305805 | J99: FALSE | K99: FALSE | L99: balance;balance_shift
A100: Velocity Park | B100: 42 | C100: random | D100: 11.41266 | E100: 29.512447 | F100: 0.047834191 | G100: 0.075372894 | H100: 51.344784 | I100: 51.344784 | J100: FALSE | K100: FALSE | L100: balance_shift
A101: Apex Ring | B101: 42 | C101: local | D101: 15.624341 | E101: 14.458158 | F101: 0.029872162 | G101: 0.058321284 | H101: 38.233459 | I101: 38.233459 | J101: TRUE | K101: TRUE
A102: Apex Ring | B102: 42 | C102: local | D102: 15.624341 | E102: 14.278271 | F102: 0.029872162 | G102: 0.058321284 | H102: 38.236318 | I102: 38.236318 | J102: TRUE | K102: TRUE
A103: Apex Ring | B103: 42 | C103: local | D103: 15.624341 | E103: 14.648039 | F103: 0.029872162 | G103: 0.058321284 | H103: 38.239838 | I103: 38.239838 | J103: TRUE | K103: FALSE
A104: Apex Ring | B104: 42 | C104: local | D104: 15.624341 | E104: 14.72136 | F104: 0.029872162 | G104: 0.058321284 | H104: 38.242743 | I104: 38.242743 | J104: TRUE | K104: FALSE
A105: Apex Ring | B105: 42 | C105: local | D105: 15.624341 | E105: 13.987208 | F105: 0.029872162 | G105: 0.058321284 | H105: 38.25608 | I105: 38.25608 | J105: TRUE | K105: TRUE
A106: Apex Ring | B106: 42 | C106: local | D106: 15.624341 | E106: 15.194247 | F106: 0.029872162 | G106: 0.058321284 | H106: 38.261996 | I106: 38.261996 | J106: TRUE | K106: FALSE
A107: Apex Ring | B107: 42 | C107: local | D107: 15.624341 | E107: 15.655946 | F107: 0.029872162 | G107: 0.058321284 | H107: 38.282509 | I107: 38.282509 | J107: TRUE | K107: FALSE
A108: Apex Ring | B108: 42 | C108: local | D108: 15.627674 | E108: 15.655946 | F108: 0.029872162 | G108: 0.058321284 | H108: 38.282555 | I108: 38.282555 | J108: TRUE | K108: FALSE
A109: Apex Ring | B109: 42 | C109: local | D109: 15.617991 | E109: 15.655946 | F109: 0.029872162 | G109: 0.058321284 | H109: 38.282615 | I109: 38.282615 | J109: TRUE | K109: FALSE
A110: Apex Ring | B110: 42 | C110: local | D110: 15.634615 | E110: 15.655946 | F110: 0.029872162 | G110: 0.058321284 | H110: 38.282653 | I110: 38.282653 | J110: TRUE | K110: FALSE
A111: Apex Ring | B111: 42 | C111: local | D111: 15.644294 | E111: 15.655946 | F111: 0.029872162 | G111: 0.058321284 | H111: 38.28279 | I111: 38.28279 | J111: TRUE | K111: FALSE
A112: Apex Ring | B112: 42 | C112: local | D112: 15.647627 | E112: 15.655946 | F112: 0.029872162 | G112: 0.058321284 | H112: 38.282837 | I112: 38.282837 | J112: TRUE | K112: FALSE
... A192: Apex Ring | B192: 42 | C192: differential_evolution | D192: 24.426885 | E192: 29.089186 | F192: 0.054678883 | G192: 0.041683727 | H192: 40.388521 | I192: 40.388521 | J192: TRUE | K192: TRUE
A193: Apex Ring | B193: 42 | C193: random | D193: 10.340681 | E193: 11.800957 | F193: 0.046670781 | G193: 0.060784475 | H193: 39.051661 | I193: 39.051661 | J193: FALSE | K193: FALSE | L193: braking_limit
A194: Apex Ring | B194: 42 | C194: differential_evolution | D194: 23.207962 | E194: 11.188393 | F194: 0.050496062 | G194: 0.052069082 | H194: 39.563496 | I194: 39.563496 | J194: FALSE | K194: FALSE | L194: balance;balance_shift
A195: Apex Ring | B195: 42 | C195: random | D195: 11.41266 | E195: 29.512447 | F195: 0.047834191 | G195: 0.075372894 | H195: 40.360128 | I195: 40.360128 | J195: FALSE | K195: FALSE | L195: balance_shift
A196: Apex Ring | B196: 43 | C196: local | D196: 14.999986 | E196: 14.053511 | F196: 0.036404688 | G196: 0.071519382 | H196: 38.27594 | I196: 38.27594 | J196: TRUE | K196: TRUE
A197: Apex Ring | B197: 43 | C197: local | D197: 14.999986 | E197: 13.619769 | F197: 0.036404688 | G197: 0.071519382 | H197: 38.280877 | I197: 38.280877 | J197: TRUE | K197: TRUE
A198: Apex Ring | B198: 43 | C198: local | D198: 14.999986 | E198: 14.269094 | F198: 0.036404688 | G198: 0.071519382 | H198: 38.283248 | I198: 38.283248 | J198: TRUE | K198: FALSE
...

Sheet Charts
A2: Charts
A3: SYNTHETIC RESEARCH MODEL | SI units | model 1.0.0
A5: speed_mps | B5: downforce_n | C5: drag_n
A6: 0 | B6: ='Aero Calculations'!C6 -> 0 | C6: ='Aero Calculations'!D6 -> 0
A7: 5 | B7: ='Aero Calculations'!C7 -> 68.90625 | C7: ='Aero Calculations'!D7 -> 20.671875
A8: 10 | B8: ='Aero Calculations'!C8 -> 275.625 | C8: ='Aero Calculations'!D8 -> 82.6875
A9: 15 | B9: ='Aero Calculations'!C9 -> 620.15625 | C9: ='Aero Calculations'!D9 -> 186.04688
A10: 20 | B10: ='Aero Calculations'!C10 -> 1102.5 | C10: ='Aero Calculations'!D10 -> 330.75
A11: 25 | B11: ='Aero Calculations'!C11 -> 1722.6562 | C11: ='Aero Calculations'!D11 -> 516.79688
A12: 30 | B12: ='Aero Calculations'!C12 -> 2480.625 | C12: ='Aero Calculations'!D12 -> 744.1875
A13: 35 | B13: ='Aero Calculations'!C13 -> 3376.4062 | C13: ='Aero Calculations'!D13 -> 1012.9219
A14: 40 | B14: ='Aero Calculations'!C14 -> 4410 | C14: ='Aero Calculations'!D14 -> 1323
A15: 45 | B15: ='Aero Calculations'!C15 -> 5581.4062 | C15: ='Aero Calculations'!D15 -> 1674.4219
A16: 50 | B16: ='Aero Calculations'!C16 -> 6890.625 | C16: ='Aero Calculations'!D16 -> 2067.1875
A17: 55 | B17: ='Aero Calculations'!C17 -> 8337.6563 | C17: ='Aero Calculations'!D17 -> 2501.2969
... A26: 100 | B26: ='Aero Calculations'!C26 -> 27562.5 | C26: ='Aero Calculations'!D26 -> 8268.75

Sheet Vehicle Inputs
A2: Vehicle Inputs
A3: SYNTHETIC RESEARCH MODEL | SI units | model 1.0.0
A5: parameter | B5: value | C5: source
A6: dry_mass_kg | B6: ='Car Inputs'!B6 -> 800 | C6: Assumed generic car
A7: wheelbase_m | B7: ='Car Inputs'!B7 -> 3.6 | C7: Assumed generic car
A8: track_m | B8: ='Car Inputs'!B8 -> 1.6 | C8: Assumed generic car
A9: cg_height_m | B9: ='Car Inputs'!B9 -> 0.3 | C9: Assumed generic car
A10: front_weight_fraction | B10: ='Car Inputs'!B10 -> 0.45 | C10: Assumed generic car
A11: area_m2 | B11: ='Car Inputs'!B11 -> 1.5 | C11: Assumed generic car
A12: power_w | B12: ='Car Inputs'!B12 -> 450000 | C12: Assumed generic car
A13: efficiency | B13: ='Car Inputs'!B13 -> 0.92 | C13: Assumed generic car
A14: rolling_coefficient | B14: ='Car Inputs'!B14 -> 0.015 | C14: Assumed generic car
A15: brake_limit_n | B15: ='Car Inputs'!B15 -> 24000 | C15: Assumed generic car
A16: brake_bias | B16: ='Car Inputs'!B16 -> 0.58 | C16: Assumed generic car
A17: wheel_radius_m | B17: ='Car Inputs'!B17 -> 0.33 | C17: Assumed generic car
... A22: roll_front_fraction | B22: ='Car Inputs'!B22 -> 0.48 | C22: Assumed generic car

Sheet Simulation Settings
A2: Simulation Settings
A3: SYNTHETIC RESEARCH MODEL | SI units | model 1.0.0
A5: setting | B5: value
A6: step_m | B6: 10
A7: speed_cap_mps | B7: 100
A8: fuel_kg_per_m | B8: 0.0005
A9: max_iterations | B9: 80
A10: speed_tolerance_mps | B10: 0.001
A11: shift_time_s | B11: 0.04
A12: race_laps | B12: 10

Sheet Segment Simulation
A2: Segment Simulation
A3: SYNTHETIC RESEARCH MODEL | SI units | model 1.0.0
A5: segment_id | B5: sector_id | C5: segment_time_s | D5: length_m | E5: top_speed_mps
A6: 201 | B6: 21 | C6: 7.8030154 | D6: 650 | E6: 89.015598
A7: 202 | B7: 21 | C7: 4.1962954 | D7: 220 | E7: 52.997505
A8: 203 | B8: 22 | C8: 7.9218776 | D8: 500 | E8: 77.352402
A9: 204 | B9: 22 | C9: 6.6081038 | D9: 200 | E9: 30.267591
A10: 205 | B10: 23 | C10: 8.8416301 | D10: 550 | E10: 79.785011
A11: 206 | B11: 23 | C11: 2.9774865 | D11: 240 | E11: 82.889666

Sheet Speed Trace
A2: Speed Trace
A3: SYNTHETIC RESEARCH MODEL | SI units | model 1.0.0
A4: Apex Ring qualifying recommendation. Integrated simulation snapshot.
A5: distance_m | B5: time_s | C5: dt_s | D5: speed_mps | E5: exit_speed_mps | F5: acceleration_mps2 | G5: gear | H5: drs
A6: 0 | B6: 0 | C6: 0.12067744 | D6: 82.813919 | E6: 82.917134 | F6: 0.85529785 | G6: 5 | H6: 0
A7: 10 | B7: 0.12067744 | C7: 0.1205292 | D7: 82.917134 | E7: 83.017754 | F7: 0.83481391 | G7: 5 | H7: 0
A8: 20 | B8: 0.24120665 | C8: 0.12038504 | D8: 83.017754 | E8: 83.115851 | F8: 0.81486055 | G8: 5 | H8: 0
A9: 30 | B9: 0.36159168 | C9: 0.12024481 | D9: 83.115851 | E9: 83.211495 | F9: 0.7954112 | G9: 5 | H9: 0
A10: 40 | B10: 0.48183649 | C10: 0.1201084 | D10: 83.211495 | E10: 83.304753 | F10: 0.77645169 | G10: 5 | H10: 0
A11: 50 | B11: 0.60194489 | C11: 0.11997568 | D11: 83.304753 | E11: 83.395691 | F11: 0.75796829 | G11: 5 | H11: 0
A12: 60 | B12: 0.72192058 | C12: 0.11984655 | D12: 83.395691 | E12: 83.484371 | F12: 0.73994777 | G12: 5 | H12: 0
A13: 70 | B13: 0.84176713 | C13: 0.11972089 | D13: 83.484371 | E13: 83.570855 | F13: 0.72237732 | G13: 5 | H13: 0
A14: 80 | B14: 0.96148802 | C14: 0.11959859 | D14: 83.570855 | E14: 83.655201 | F14: 0.70524454 | G14: 5 | H14: 0
A15: 90 | B15: 1.0810866 | C15: 0.11947955 | D15: 83.655201 | E15: 83.737467 | F15: 0.68853747 | G15: 5 | H15: 0
A16: 100 | B16: 1.2005661 | C16: 0.11928438 | D16: 83.737467 | E16: 83.929073 | F16: 1.6062936 | G16: 5 | H16: 1
A17: 110 | B17: 1.3198505 | C17: 0.11901552 | D17: 83.929073 | E17: 84.116235 | F17: 1.5725807 | G17: 5 | H17: 1
... A241: 2350 | B241: 38.227656 | C241: 0.12075265 | D241: 82.813919 | E241: 82.813919 | F241: 0 | G241: 5 | H241: 0

Sheet Force Breakdown
A2: Force Breakdown
A3: SYNTHETIC RESEARCH MODEL | SI units | model 1.0.0
A5: distance_m | B5: engine_force_n | C5: brake_force_n | D5: drag_n | E5: rolling_force_n | F5: downforce_n | G5: front_tyre_load_n | H5: rear_tyre_load_n
A6: 0 | B6: 4999.1603 | C6: 0 | D6: 3884.2693 | E6: 422.09975 | F6: 20196.597 | G6: 12471.796 | H6: 15668.188
A7: 10 | B7: 4992.9279 | C7: 0 | D7: 3893.902 | E7: 422.8308 | F7: 20245.383 | G7: 12494.857 | H7: 15693.863
A8: 20 | B8: 4986.8768 | C8: 0 | D8: 3903.3037 | E8: 423.54417 | F8: 20292.99 | G8: 12517.358 | H8: 15718.92
A9: 30 | B9: 4980.9917 | C9: 0 | D9: 3912.4803 | E9: 424.24032 | F9: 20339.449 | G9: 12539.316 | H9: 15743.372
A10: 40 | B10: 4975.2675 | C10: 0 | D10: 3921.4375 | E10: 424.91969 | F10: 20384.789 | G10: 12560.743 | H10: 15767.237
A11: 50 | B11: 4969.699 | C11: 0 | D11: 3930.1809 | E11: 425.58272 | F11: 20429.04 | G11: 12581.653 | H11: 15790.528
A12: 60 | B12: 4964.2812 | C12: 0 | D12: 3938.7159 | E12: 426.22981 | F12: 20472.228 | G12: 12602.06 | H12: 15813.26
A13: 70 | B13: 4959.0093 | C13: 0 | D13: 3947.0476 | E13: 426.86138 | F13: 20514.382 | G13: 12621.977 | H13: 15835.448
A14: 80 | B14: 4953.8789 | C14: 0 | D14: 3955.1812 | E14: 427.47781 | F14: 20555.526 | G14: 12641.416 | H14: 15857.105
A15: 90 | B15: 4948.8856 | C15: 0 | D15: 3963.1217 | E15: 428.07949 | F15: 20595.688 | G15: 12660.388 | H15: 15878.245
A16: 100 | B16: 4944.0248 | C16: 0 | D16: 3257.0114 | E16: 385.99593 | F16: 17790.166 | G16: 12628.335 | H16: 13104.727
A17: 110 | B17: 4932.739 | C17: 0 | D17: 3271.8531 | E17: 387.18201 | F17: 17869.287 | G17: 12671.445 | H17: 13140.689
... A241: 2350 | B241: 4304.727 | C241: 0 | D241: 3884.2889 | E241: 420.43811 | F241: 20097.344 | G241: 12480.311 | H241: 15548.897

Sheet Tyre State
A2: Tyre State
A3: SYNTHETIC RESEARCH MODEL | SI units | model 1.0.0
A5: distance_m | B5: tyre_wear | C5: tyre_temperature_c | D5: tyre_mu | E5: max_wheel_load_n
A6: 0 | B6: 0 | C6: 85 | D6: 1.4483748 | E6: 7834.0938
A7: 10 | B7: 8.6752531e-05 | C7: 85.127708 | D7: 1.4484572 | E7: 7846.9316
A8: 20 | B8: 0.00017365222 | C8: 85.255236 | D8: 1.4485334 | E8: 7859.4598
A9: 30 | B9: 0.0002606954 | C9: 85.382578 | D9: 1.4486032 | E9: 7871.6862
A10: 40 | B10: 0.00034787861 | C10: 85.509729 | D10: 1.4486666 | E10: 7883.6184
A11: 50 | B11: 0.00043519846 | C11: 85.636685 | D11: 1.4487234 | E11: 7895.264
A12: 60 | B12: 0.00052265164 | C12: 85.76344 | D12: 1.4487736 | E12: 7906.6302
A13: 70 | B13: 0.00061023496 | C13: 85.88999 | D13: 1.4488169 | E13: 7917.7241
A14: 80 | B14: 0.00069794527 | C14: 86.016329 | D14: 1.4488534 | E14: 7928.5526
A15: 90 | B15: 0.00078577953 | C15: 86.142455 | D15: 1.4488829 | E15: 7939.1223
A16: 100 | B16: 0.00087373478 | C16: 86.268362 | D16: 1.4633852 | E16: 6552.3635
A17: 110 | B17: 0.00095288632 | C17: 86.379202 | D17: 1.4631482 | E17: 6570.3447
... A241: 2350 | B241: 0.016779876 | C241: 101.63257 | D241: 1.3731628 | E241: 11380.024

Sheet Fuel State
A2: Fuel State
A3: SYNTHETIC RESEARCH MODEL | SI units | model 1.0.0
A5: distance_m | B5: fuel_kg | C5: mass_kg
A6: 0 | B6: 10 | C6: 810
A7: 10 | B7: 9.995 | C7: 809.995
A8: 20 | B8: 9.99 | C8: 809.99
A9: 30 | B9: 9.985 | C9: 809.985
A10: 40 | B10: 9.98 | C10: 809.98
A11: 50 | B11: 9.975 | C11: 809.975
A12: 60 | B12: 9.97 | C12: 809.97
A13: 70 | B13: 9.965 | C13: 809.965
A14: 80 | B14: 9.96 | C14: 809.96
A15: 90 | B15: 9.955 | C15: 809.955
A16: 100 | B16: 9.95 | C16: 809.95
A17: 110 | B17: 9.945 | C17: 809.945
... A241: 2350 | B241: 8.825 | C241: 808.825

Sheet Car Inputs
A2: Car Inputs
A3: SYNTHETIC RESEARCH MODEL | SI units | model 1.0.0
A5: parameter | B5: value | C5: source
A6: dry_mass_kg | B6: 800 | C6: Assumed generic car
A7: wheelbase_m | B7: 3.6 | C7: Assumed generic car
A8: track_m | B8: 1.6 | C8: Assumed generic car
A9: cg_height_m | B9: 0.3 | C9: Assumed generic car
A10: front_weight_fraction | B10: 0.45 | C10: Assumed generic car
A11: area_m2 | B11: 1.5 | C11: Assumed generic car
A12: power_w | B12: 450000 | C12: Assumed generic car
A13: efficiency | B13: 0.92 | C13: Assumed generic car
A14: rolling_coefficient | B14: 0.015 | C14: Assumed generic car
A15: brake_limit_n | B15: 24000 | C15: Assumed generic car
A16: brake_bias | B16: 0.58 | C16: Assumed generic car
A17: wheel_radius_m | B17: 0.33 | C17: Assumed generic car
... A22: roll_front_fraction | B22: 0.48 | C22: Assumed generic car

Sheet Circuit Inputs
A2: Circuit Inputs
A3: SYNTHETIC RESEARCH MODEL | SI units | model 1.0.0
A5: circuit_id | B5: circuit_name | C5: length_m | D5: data_source_type | E5: synthetic_flag
A6: 1 | B6: Velocity Park | C6: 2940 | D6: synthetic | E6: TRUE
A7: 2 | B7: Apex Ring | C7: 2360 | D7: synthetic | E7: TRUE
A8: 3 | B8: Downforce Circuit | C8: 2060 | D8: synthetic | E8: TRUE

Sheet Sector Inputs
A2: Sector Inputs
A3: SYNTHETIC RESEARCH MODEL | SI units | model 1.0.0
A5: sector_id | B5: circuit_id | C5: sector_name | D5: data_source_type | E5: synthetic_flag
A6: 11 | B6: 1 | C6: Sector 1 | D6: synthetic | E6: TRUE
A7: 12 | B7: 1 | C7: Sector 2 | D7: synthetic | E7: TRUE
A8: 13 | B8: 1 | C8: Sector 3 | D8: synthetic | E8: TRUE
A9: 21 | B9: 2 | C9: Sector 1 | D9: synthetic | E9: TRUE
A10: 22 | B10: 2 | C10: Sector 2 | D10: synthetic | E10: TRUE
A11: 23 | B11: 2 | C11: Sector 3 | D11: synthetic | E11: TRUE
A12: 31 | B12: 3 | C12: Sector 1 | D12: synthetic | E12: TRUE
A13: 32 | B13: 3 | C13: Sector 2 | D13: synthetic | E13: TRUE
A14: 33 | B14: 3 | C14: Sector 3 | D14: synthetic | E14: TRUE

Sheet Corner Inputs
A2: Corner Inputs
A3: SYNTHETIC RESEARCH MODEL | SI units | model 1.0.0
A5: corner_id | B5: sector_id | C5: radius_m | D5: banking_rad | E5: width_m | F5: data_source_type | G5: synthetic_flag
A6: 102 | B6: 11 | C6: 75 | D6: 0.02 | E6: 12 | F6: synthetic | G6: TRUE
A7: 104 | B7: 12 | C7: 40 | D7: -0.01 | E7: 12 | F7: synthetic | G7: TRUE
A8: 106 | B8: 13 | C8: 110 | D8: 0 | E8: 12 | F8: synthetic | G8: TRUE
A9: 202 | B9: 21 | C9: 95 | D9: 0.02 | E9: 12 | F9: synthetic | G9: TRUE
A10: 204 | B10: 22 | C10: 50 | D10: -0.01 | E10: 12 | F10: synthetic | G10: TRUE
A11: 206 | B11: 23 | C11: 150 | D11: 0 | E11: 12 | F11: synthetic | G11: TRUE
A12: 302 | B12: 31 | C12: 160 | D12: 0.02 | E12: 12 | F12: synthetic | G12: TRUE
A13: 304 | B13: 32 | C13: 110 | D13: -0.01 | E13: 12 | F13: synthetic | G13: TRUE
A14: 306 | B14: 33 | C14: 210 | D14: 0 | E14: 12 | F14: synthetic | G14: TRUE

Sheet Tyre Inputs
A2: Tyre Inputs
A3: SYNTHETIC RESEARCH MODEL | SI units | model 1.0.0
A5: tyre_id | B5: name | C5: mu | D5: wear_per_m | E5: optimal_temp_c | F5: load_exponent | G5: reference_load_n | H5: data_source_type | I5: synthetic_flag
A6: 1 | B6: Soft | C6: 1.68 | D6: 3e-06 | E6: 90 | F6: 0.09 | G6: 2500 | H6: synthetic | I6: TRUE
A7: 2 | B7: Medium | C7: 1.6 | D7: 2e-06 | E7: 90 | F7: 0.09 | G7: 2500 | H7: synthetic | I7: TRUE
A8: 3 | B8: Hard | C8: 1.52 | D8: 1.4e-06 | E8: 90 | F8: 0.09 | G8: 2500 | H8: synthetic | I8: TRUE

Sheet Weather Inputs
A2: Weather Inputs
A3: SYNTHETIC RESEARCH MODEL | SI units | model 1.0.0
A5: weather_id | B5: name | C5: pressure_pa | D5: temperature_k | E5: grip | F5: headwind_mps | G5: crosswind_mps | H5: aero_multiplier | I5: density_multiplier | J5: height_offset_m | K5: data_source_type | L5: synthetic_flag
A6: 1 | B6: Dry | C6: 101325 | D6: 288.15 | E6: 1 | F6: 0 | G6: 0 | H6: 1 | I6: 1 | J6: 0 | K6: synthetic | L6: TRUE
A7: 2 | B7: Hot | C7: 97000 | D7: 310.15 | E7: 0.97 | F7: 0 | G7: 0 | H7: 1 | I7: 1 | J7: 0 | K7: synthetic | L7: TRUE
A8: 3 | B8: Wet | C8: 100500 | D8: 285.15 | E8: 0.68 | F8: 0 | G8: 0 | H8: 1 | I8: 1 | J8: 0 | K8: synthetic | L8: TRUE

Sheet Aero Map
A2: Aero Map
A3: SYNTHETIC RESEARCH MODEL | SI units | model 1.0.0
A5: aero_map_id | B5: setup_id | C5: speed_mps | D5: front_height_m | E5: rear_height_m | F5: yaw_deg | G5: drs | H5: cl_front | I5: cl_rear | J5: cd | K5: downforce_n | L5: drag_n | M5: data_source_type | N5: synthetic_flag
A6: 1 | B6: 1 | C6: 0 | D6: 0.025 | E6: 0.04 | F6: -5 | G6: 0 | H6: 1.3940998 | I6: 1.8503784 | J6: 0.76279073 | K6: 0 | L6: 0 | M6: synthetic | N6: TRUE
A7: 2 | B7: 1 | C7: 0 | D7: 0.025 | E7: 0.04 | F7: -5 | G7: 1 | H7: 1.3940998 | I7: 1.3877838 | J7: 0.6254884 | K7: 0 | L7: 0 | M7: synthetic | N7: TRUE
A8: 3 | B8: 1 | C8: 0 | D8: 0.025 | E8: 0.04 | F8: 0 | G8: 0 | H8: 1.4258226 | I8: 1.8924839 | J8: 0.75529073 | K8: 0 | L8: 0 | M8: synthetic | N8: TRUE
A9: 4 | B9: 1 | C9: 0 | D9: 0.025 | E9: 0.04 | F9: 0 | G9: 1 | H9: 1.4258226 | I9: 1.4193629 | J9: 0.6193384 | K9: 0 | L9: 0 | M9: synthetic | N9: TRUE
A10: 5 | B10: 1 | C10: 0 | D10: 0.025 | E10: 0.04 | F10: 5 | G10: 0 | H10: 1.3940998 | I10: 1.8503784 | J10: 0.76279073 | K10: 0 | L10: 0 | M10: synthetic | N10: TRUE
A11: 6 | B11: 1 | C11: 0 | D11: 0.025 | E11: 0.04 | F11: 5 | G11: 1 | H11: 1.3940998 | I11: 1.3877838 | J11: 0.6254884 | K11: 0 | L11: 0 | M11: synthetic | N11: TRUE
A12: 7 | B12: 1 | C12: 0 | D12: 0.025 | E12: 0.06 | F12: -5 | G12: 0 | H12: 1.4347148 | I12: 1.911301 | J12: 0.76642541 | K12: 0 | L12: 0 | M12: synthetic | N12: TRUE
A13: 8 | B13: 1 | C13: 0 | D13: 0.025 | E13: 0.06 | F13: -5 | G13: 1 | H13: 1.4347148 | I13: 1.4334757 | J13: 0.62846883 | K13: 0 | L13: 0 | M13: synthetic | N13: TRUE
A14: 9 | B14: 1 | C14: 0 | D14: 0.025 | E14: 0.06 | F14: 0 | G14: 0 | H14: 1.4673618 | I14: 1.9547927 | J14: 0.75892541 | K14: 0 | L14: 0 | M14: synthetic | N14: TRUE
A15: 10 | B15: 1 | C15: 0 | D15: 0.025 | E15: 0.06 | F15: 0 | G15: 1 | H15: 1.4673618 | I15: 1.4660945 | J15: 0.62231883 | K15: 0 | L15: 0 | M15: synthetic | N15: TRUE
A16: 11 | B16: 1 | C16: 0 | D16: 0.025 | E16: 0.06 | F16: 5 | G16: 0 | H16: 1.4347148 | I16: 1.911301 | J16: 0.76642541 | K16: 0 | L16: 0 | M16: synthetic | N16: TRUE
A17: 12 | B17: 1 | C17: 0 | D17: 0.025 | E17: 0.06 | F17: 5 | G17: 1 | H17: 1.4347148 | I17: 1.4334757 | J17: 0.62846883 | K17: 0 | L17: 0 | M17: synthetic | N17: TRUE
... A3245: 3240 | B3245: 12 | C3245: 90 | D3245: 0.055 | E3245: 0.085 | F3245: 5 | G3245: 1 | H3245: 1.1987636 | I3245: 1.3097728 | J3245: 0.72167002 | K3245: 18668.215 | L3245: 5370.578 | M3245: synthetic | N3245: TRUE

Sheet Setup Scenarios
A2: Setup Scenarios
A3: SYNTHETIC RESEARCH MODEL | SI units | model 1.0.0
A5: setup_id | B5: setup_name | C5: front_wing_deg | D5: rear_wing_deg | E5: front_height_m | F5: rear_height_m | G5: package
A6: 1 | B6: Baseline | C6: 17.5 | D6: 20 | E6: 0.04 | F6: 0.06 | G6: standard
A7: 2 | B7: Candidate 01 | C7: 20.787473 | D7: 19.022055 | E7: 0.04860635 | F7: 0.069605249 | G7: standard
A8: 3 | B8: Candidate 02 | C8: 12.630128 | D8: 27.609958 | E8: 0.046267353 | F8: 0.072798315 | G8: standard
A9: 4 | B9: Candidate 03 | C9: 13.037364 | D9: 19.206175 | E9: 0.036899153 | F9: 0.07786354 | G9: standard
A10: 5 | B10: Candidate 04 | C10: 19.226381 | D10: 25.164186 | E10: 0.038641941 | F10: 0.052680594 | G10: standard
A11: 6 | B11: Candidate 05 | C11: 18.155017 | D11: 13.021076 | E11: 0.047863148 | F11: 0.067239918 | G11: standard
A12: 7 | B12: Candidate 06 | C12: 20.597053 | D12: 17.672415 | E12: 0.051296753 | F12: 0.07665236 | G12: standard
A13: 8 | B13: Candidate 07 | C13: 20.840602 | D13: 15.114219 | E13: 0.039201304 | F13: 0.046076936 | G13: standard
A14: 9 | B14: Candidate 08 | C14: 13.351474 | D14: 22.928783 | E14: 0.045874292 | F14: 0.07933035 | G14: standard
A15: 10 | B15: Candidate 09 | C15: 15.409904 | D15: 17.927355 | E15: 0.039269339 | F15: 0.051320969 | G15: standard
A16: 11 | B16: Candidate 10 | C16: 13.059058 | D16: 19.611279 | E16: 0.033445824 | F16: 0.068613304 | G16: standard
A17: 12 | B17: Candidate 11 | C17: 16.745823 | D17: 25.322851 | E17: 0.044806362 | F17: 0.055745199 | G17: standard
... A20: 15 | B20: Downforce Circuit qualifying | C20: 12.477897 | D20: 10.038388 | E20: 0.038372825 | F20: 0.055092893 | G20: standard

Sheet Data Quality
A2: Data Quality
A3: SYNTHETIC RESEARCH MODEL | SI units | model 1.0.0
A4: Missing cells in rejected evaluations are explicit unavailable outputs, not zero.
A5: table_name | B5: row_count | C5: duplicate_rows | D5: missing_cells | E5: synthetic_percentage
A6: dim_car | B6: 1 | C6: 0 | D6: 0 | E6: 100
A7: dim_circuit | B7: 3 | C7: 0 | D7: 0 | E7: 100
A8: dim_setup | B8: 15 | C8: 0 | D8: 0 | E8: 100
A9: dim_weather | B9: 3 | C9: 0 | D9: 0 | E9: 100
A10: dim_tyre | B10: 3 | C10: 0 | D10: 0 | E10: 100
A11: dim_driver | B11: 1 | C11: 0 | D11: 0 | E11: 100
A12: dim_date | B12: 1 | C12: 0 | D12: 0 | E12: 100
A13: dim_session | B13: 3 | C13: 0 | D13: 0 | E13: 100
A14: dim_sector | B14: 9 | C14: 0 | D14: 0 | E14: 100
A15: dim_corner | B15: 9 | C15: 0 | D15: 0 | E15: 100
A16: fact_aero_map | B16: 3240 | C16: 0 | D16: 0 | E16: 100
A17: run_registry | B17: 133 | C17: 0 | D17: 0 | E17: 100
... A21: fact_tyre_state | B21: 6569 | C21: 0 | D21: 0 | E21: 100
A22: fact_simulation_warning | B22: 0 | C22: 0 | D22: 0
A23: fact_optimization_run | B23: 11 | C23: 0 | D23: 0 | E23: 100
A24: fact_optimization_result | B24: 746 | C24: 0 | D24: 0 | E24: 100
A25: fact_model_validation | B25: 1064 | C25: 0 | D25: 0 | E25: 100
A26: fact_lap | B26: 0 | C26: 0 | D26: 0
A27: fact_sector | B27: 0 | C27: 0 | D27: 0
A28: fact_telemetry | B28: 0 | C28: 0 | D28: 0
A29: dim_track_segment | B29: 18 | C29: 0 | D29: 0 | E29: 100
A30: fact_vehicle_state | B30: 32424 | C30: 0 | D30: 0 | E30: 100
A31: fact_simulation_segment | B31: 798 | C31: 0 | D31: 0 | E31: 100

Sheet Python Reconciliation
A2: Python Reconciliation
A3: SYNTHETIC RESEARCH MODEL | SI units | model 1.0.0
A4: Recalculate with Excel; cached Python values are not used as proof.
A5: quantity | B5: python_reference | C5: excel_result | D5: difference
A6: Dynamic pressure | B6: 1531.25 | C6: ='Aero Calculations'!B16 -> 1531.25 | D6: =C6-B6 -> 0
A7: Downforce | B7: 6890.625 | C7: ='Aero Calculations'!C16 -> 6890.625 | D7: =C7-B7 -> 0
A8: Drag | B8: 2067.1875 | C8: ='Aero Calculations'!D16 -> 2067.1875 | D8: =C8-B8 -> 0
A9: Drag power | B9: 103359.38 | C9: ='Aero Calculations'!J16 -> 103359.38 | D9: =C9-B9 -> 0
A10: Lap sector sum | B10: 38.348409 | C10: =SUM('Sector Comparison'!C6:C8) -> 38.348409 | D10: =C10-B10 -> 0

Sheet MySQL Reconciliation
A2: MySQL Reconciliation
A3: SYNTHETIC RESEARCH MODEL | SI units | model 1.0.0
A5: table_name | B5: python_rows | C5: mysql_rows | D5: matched
A6: dim_car | B6: 1 | C6: 1 | D6: TRUE
A7: dim_circuit | B7: 3 | C7: 3 | D7: TRUE
A8: dim_date | B8: 1 | C8: 1 | D8: TRUE
A9: dim_driver | B9: 1 | C9: 1 | D9: TRUE
A10: dim_sector | B10: 9 | C10: 9 | D10: TRUE
A11: dim_session | B11: 3 | C11: 3 | D11: TRUE
A12: dim_setup | B12: 15 | C12: 15 | D12: TRUE
A13: dim_track_segment | B13: 18 | C13: 18 | D13: TRUE
A14: dim_tyre | B14: 3 | C14: 3 | D14: TRUE
A15: dim_weather | B15: 3 | C15: 3 | D15: TRUE
A16: fact_aero_map | B16: 3240 | C16: 3240 | D16: TRUE
A17: fact_optimization_run | B17: 11 | C17: 11 | D17: TRUE
... A32: lap_time_sum_s | B32: 5519.901 | C32: 5519.901 | D32: TRUE

Sheet Unit Reference
A2: Unit Reference
A3: SYNTHETIC RESEARCH MODEL | SI units | model 1.0.0
A5: quantity | B5: storage_unit | C5: definition
A6: Speed | B6: m/s | C6: km/h = m/s × 3.6
A7: Force | B7: N | C7: Positive downforce convention
A8: Pressure | B8: Pa | C8: Absolute local static pressure
A9: Temperature | B9: K | C9: Kelvin = Celsius + 273.15
A10: Angles | B10: rad | C10: Setup UI wing angles in degrees
A11: Time | B11: s | C11: Negative candidate delta means faster

Sheet Project Scope
A2: Project Scope
A3: SYNTHETIC RESEARCH MODEL | SI units | model 1.0.0
A5: status | B5: description
A6: Implemented | B6: Quasi-static synthetic car, lap/stint solver, constraints and search
A7: Assumed | B7: Aero response, tyre/load coefficients, suspension compliance and DRS policy
A8: Not measured | B8: No proprietary telemetry; no real-car accuracy claim
A9: Future | B9: Transient suspension, full slip/thermal tyres, calibrated aero and current regulation model

Sheet README
A2: README
A3: SYNTHETIC RESEARCH MODEL | SI units | model 1.0.0
A5: topic | B5: guidance
A6: Purpose | B6: Compare synthetic aerodynamic setups and inspect engineering equations
A7: Inputs | B7: Blue cells are editable; formula cells are protected without a password
A8: Refresh | B8: Run the Python pipeline and rebuild this workbook to refresh simulation snapshots
A9: Live formulas | B9: Aero Calculations and limiting-case examples recalculate with editable inputs
A10: Synthetic status | B10: All simulations and aerodynamic data are synthetic
A11: Comparison | B11: Match circuit, weather, tyre, fuel and session before comparing times
A12: Reconciliation | B12: Python Reconciliation is checked after actual Excel recalculation
A13: Limitations | B13: No measured-car validation; do not use as a real-car safety approval
